Traceback (most recent call last):
  File "/Users/Hunter/opt/anaconda3/lib/python3.8/site-packages/jupyter_cache/executors/utils.py", line 51, in single_nb_execution
    executenb(
  File "/Users/Hunter/opt/anaconda3/lib/python3.8/site-packages/nbclient/client.py", line 1112, in execute
    return NotebookClient(nb=nb, resources=resources, km=km, **kwargs).execute()
  File "/Users/Hunter/opt/anaconda3/lib/python3.8/site-packages/nbclient/util.py", line 74, in wrapped
    return just_run(coro(*args, **kwargs))
  File "/Users/Hunter/opt/anaconda3/lib/python3.8/site-packages/nbclient/util.py", line 53, in just_run
    return loop.run_until_complete(coro)
  File "/Users/Hunter/opt/anaconda3/lib/python3.8/asyncio/base_events.py", line 616, in run_until_complete
    return future.result()
  File "/Users/Hunter/opt/anaconda3/lib/python3.8/site-packages/nbclient/client.py", line 553, in async_execute
    await self.async_execute_cell(
  File "/Users/Hunter/opt/anaconda3/lib/python3.8/site-packages/nbclient/client.py", line 857, in async_execute_cell
    self._check_raise_for_error(cell, exec_reply)
  File "/Users/Hunter/opt/anaconda3/lib/python3.8/site-packages/nbclient/client.py", line 760, in _check_raise_for_error
    raise CellExecutionError.from_cell_and_msg(cell, exec_reply_content)
nbclient.exceptions.CellExecutionError: An error occurred while executing the following cell:
------------------
print(nums[0])
------------------

[0;31m---------------------------------------------------------------------------[0m
[0;31mTypeError[0m                                 Traceback (most recent call last)
[0;32m<ipython-input-7-055bcd253040>[0m in [0;36m<module>[0;34m[0m
[0;32m----> 1[0;31m [0mprint[0m[0;34m([0m[0mnums[0m[0;34m[[0m[0;36m0[0m[0;34m][0m[0;34m)[0m[0;34m[0m[0;34m[0m[0m
[0m
[0;31mTypeError[0m: 'set' object is not subscriptable
TypeError: 'set' object is not subscriptable

